2025-03-16 07:45:30.115 Uncaught app execution
Traceback (most recent call last):
  File "/home/azureuser/SDA/venv/lib/python3.12/site-packages/urllib3/connection.py", line 198, in _new_conn
    sock = connection.create_connection(
           ^^^^^^^^^^^^^^^^^^^^^^^^^^^^^
  File "/home/azureuser/SDA/venv/lib/python3.12/site-packages/urllib3/util/connection.py", line 85, in create_connection
    raise err
  File "/home/azureuser/SDA/venv/lib/python3.12/site-packages/urllib3/util/connection.py", line 73, in create_connection
    sock.connect(sa)
ConnectionRefusedError: [Errno 111] Connection refused

The above exception was the direct cause of the following exception:

Traceback (most recent call last):
  File "/home/azureuser/SDA/venv/lib/python3.12/site-packages/urllib3/connectionpool.py", line 787, in urlopen
    response = self._make_request(
               ^^^^^^^^^^^^^^^^^^^
  File "/home/azureuser/SDA/venv/lib/python3.12/site-packages/urllib3/connectionpool.py", line 493, in _make_request
    conn.request(
  File "/home/azureuser/SDA/venv/lib/python3.12/site-packages/urllib3/connection.py", line 445, in request
    self.endheaders()
  File "/usr/lib/python3.12/http/client.py", line 1331, in endheaders
    self._send_output(message_body, encode_chunked=encode_chunked)
  File "/usr/lib/python3.12/http/client.py", line 1091, in _send_output
    self.send(msg)
  File "/usr/lib/python3.12/http/client.py", line 1035, in send
    self.connect()
  File "/home/azureuser/SDA/venv/lib/python3.12/site-packages/urllib3/connection.py", line 276, in connect
    self.sock = self._new_conn()
                ^^^^^^^^^^^^^^^^
  File "/home/azureuser/SDA/venv/lib/python3.12/site-packages/urllib3/connection.py", line 213, in _new_conn
    raise NewConnectionError(
urllib3.exceptions.NewConnectionError: <urllib3.connection.HTTPConnection object at 0x7248c1a2d4c0>: Failed to establish a new connection: [Errno 111] Connection refused

The above exception was the direct cause of the following exception:

Traceback (most recent call last):
  File "/home/azureuser/SDA/venv/lib/python3.12/site-packages/requests/adapters.py", line 667, in send
    resp = conn.urlopen(
           ^^^^^^^^^^^^^
  File "/home/azureuser/SDA/venv/lib/python3.12/site-packages/urllib3/connectionpool.py", line 841, in urlopen
    retries = retries.increment(
              ^^^^^^^^^^^^^^^^^^
  File "/home/azureuser/SDA/venv/lib/python3.12/site-packages/urllib3/util/retry.py", line 519, in increment
    raise MaxRetryError(_pool, url, reason) from reason  # type: ignore[arg-type]
    ^^^^^^^^^^^^^^^^^^^^^^^^^^^^^^^^^^^^^^^^^^^^^^^^^^^
urllib3.exceptions.MaxRetryError: HTTPConnectionPool(host='127.0.0.1', port=5000): Max retries exceeded with url: /load_chat/ (Caused by NewConnectionError('<urllib3.connection.HTTPConnection object at 0x7248c1a2d4c0>: Failed to establish a new connection: [Errno 111] Connection refused'))

During handling of the above exception, another exception occurred:

Traceback (most recent call last):
  File "/home/azureuser/SDA/venv/lib/python3.12/site-packages/streamlit/runtime/scriptrunner/exec_code.py", line 88, in exec_func_with_error_handling
    result = func()
             ^^^^^^
  File "/home/azureuser/SDA/venv/lib/python3.12/site-packages/streamlit/runtime/scriptrunner/script_runner.py", line 579, in code_to_exec
    exec(code, module.__dict__)
  File "/home/azureuser/SDA/chatbot.py", line 112, in <module>
    load_chats_from_db()
  File "/home/azureuser/SDA/chatbot.py", line 23, in load_chats_from_db
    response = requests.get(LOAD_CHAT_URL)
               ^^^^^^^^^^^^^^^^^^^^^^^^^^^
  File "/home/azureuser/SDA/venv/lib/python3.12/site-packages/requests/api.py", line 73, in get
    return request("get", url, params=params, **kwargs)
           ^^^^^^^^^^^^^^^^^^^^^^^^^^^^^^^^^^^^^^^^^^^^
  File "/home/azureuser/SDA/venv/lib/python3.12/site-packages/requests/api.py", line 59, in request
    return session.request(method=method, url=url, **kwargs)
           ^^^^^^^^^^^^^^^^^^^^^^^^^^^^^^^^^^^^^^^^^^^^^^^^^
  File "/home/azureuser/SDA/venv/lib/python3.12/site-packages/requests/sessions.py", line 589, in request
    resp = self.send(prep, **send_kwargs)
           ^^^^^^^^^^^^^^^^^^^^^^^^^^^^^^
  File "/home/azureuser/SDA/venv/lib/python3.12/site-packages/requests/sessions.py", line 703, in send
    r = adapter.send(request, **kwargs)
        ^^^^^^^^^^^^^^^^^^^^^^^^^^^^^^^
  File "/home/azureuser/SDA/venv/lib/python3.12/site-packages/requests/adapters.py", line 700, in send
    raise ConnectionError(e, request=request)
requests.exceptions.ConnectionError: HTTPConnectionPool(host='127.0.0.1', port=5000): Max retries exceeded with url: /load_chat/ (Caused by NewConnectionError('<urllib3.connection.HTTPConnection object at 0x7248c1a2d4c0>: Failed to establish a new connection: [Errno 111] Connection refused'))
2025-03-16 07:50:19.098 Uncaught app execution
Traceback (most recent call last):
  File "/home/azureuser/SDA/venv/lib/python3.12/site-packages/urllib3/connection.py", line 198, in _new_conn
    sock = connection.create_connection(
           ^^^^^^^^^^^^^^^^^^^^^^^^^^^^^
  File "/home/azureuser/SDA/venv/lib/python3.12/site-packages/urllib3/util/connection.py", line 85, in create_connection
    raise err
  File "/home/azureuser/SDA/venv/lib/python3.12/site-packages/urllib3/util/connection.py", line 73, in create_connection
    sock.connect(sa)
ConnectionRefusedError: [Errno 111] Connection refused

The above exception was the direct cause of the following exception:

Traceback (most recent call last):
  File "/home/azureuser/SDA/venv/lib/python3.12/site-packages/urllib3/connectionpool.py", line 787, in urlopen
    response = self._make_request(
               ^^^^^^^^^^^^^^^^^^^
  File "/home/azureuser/SDA/venv/lib/python3.12/site-packages/urllib3/connectionpool.py", line 493, in _make_request
    conn.request(
  File "/home/azureuser/SDA/venv/lib/python3.12/site-packages/urllib3/connection.py", line 445, in request
    self.endheaders()
  File "/usr/lib/python3.12/http/client.py", line 1331, in endheaders
    self._send_output(message_body, encode_chunked=encode_chunked)
  File "/usr/lib/python3.12/http/client.py", line 1091, in _send_output
    self.send(msg)
  File "/usr/lib/python3.12/http/client.py", line 1035, in send
    self.connect()
  File "/home/azureuser/SDA/venv/lib/python3.12/site-packages/urllib3/connection.py", line 276, in connect
    self.sock = self._new_conn()
                ^^^^^^^^^^^^^^^^
  File "/home/azureuser/SDA/venv/lib/python3.12/site-packages/urllib3/connection.py", line 213, in _new_conn
    raise NewConnectionError(
urllib3.exceptions.NewConnectionError: <urllib3.connection.HTTPConnection object at 0x7248c1b52ff0>: Failed to establish a new connection: [Errno 111] Connection refused

The above exception was the direct cause of the following exception:

Traceback (most recent call last):
  File "/home/azureuser/SDA/venv/lib/python3.12/site-packages/requests/adapters.py", line 667, in send
    resp = conn.urlopen(
           ^^^^^^^^^^^^^
  File "/home/azureuser/SDA/venv/lib/python3.12/site-packages/urllib3/connectionpool.py", line 841, in urlopen
    retries = retries.increment(
              ^^^^^^^^^^^^^^^^^^
  File "/home/azureuser/SDA/venv/lib/python3.12/site-packages/urllib3/util/retry.py", line 519, in increment
    raise MaxRetryError(_pool, url, reason) from reason  # type: ignore[arg-type]
    ^^^^^^^^^^^^^^^^^^^^^^^^^^^^^^^^^^^^^^^^^^^^^^^^^^^
urllib3.exceptions.MaxRetryError: HTTPConnectionPool(host='127.0.0.1', port=5000): Max retries exceeded with url: /load_chat/ (Caused by NewConnectionError('<urllib3.connection.HTTPConnection object at 0x7248c1b52ff0>: Failed to establish a new connection: [Errno 111] Connection refused'))

During handling of the above exception, another exception occurred:

Traceback (most recent call last):
  File "/home/azureuser/SDA/venv/lib/python3.12/site-packages/streamlit/runtime/scriptrunner/exec_code.py", line 88, in exec_func_with_error_handling
    result = func()
             ^^^^^^
  File "/home/azureuser/SDA/venv/lib/python3.12/site-packages/streamlit/runtime/scriptrunner/script_runner.py", line 579, in code_to_exec
    exec(code, module.__dict__)
  File "/home/azureuser/SDA/chatbot.py", line 112, in <module>
    load_chats_from_db()
  File "/home/azureuser/SDA/chatbot.py", line 23, in load_chats_from_db
    response = requests.get(LOAD_CHAT_URL)
               ^^^^^^^^^^^^^^^^^^^^^^^^^^^
  File "/home/azureuser/SDA/venv/lib/python3.12/site-packages/requests/api.py", line 73, in get
    return request("get", url, params=params, **kwargs)
           ^^^^^^^^^^^^^^^^^^^^^^^^^^^^^^^^^^^^^^^^^^^^
  File "/home/azureuser/SDA/venv/lib/python3.12/site-packages/requests/api.py", line 59, in request
    return session.request(method=method, url=url, **kwargs)
           ^^^^^^^^^^^^^^^^^^^^^^^^^^^^^^^^^^^^^^^^^^^^^^^^^
  File "/home/azureuser/SDA/venv/lib/python3.12/site-packages/requests/sessions.py", line 589, in request
    resp = self.send(prep, **send_kwargs)
           ^^^^^^^^^^^^^^^^^^^^^^^^^^^^^^
  File "/home/azureuser/SDA/venv/lib/python3.12/site-packages/requests/sessions.py", line 703, in send
    r = adapter.send(request, **kwargs)
        ^^^^^^^^^^^^^^^^^^^^^^^^^^^^^^^
  File "/home/azureuser/SDA/venv/lib/python3.12/site-packages/requests/adapters.py", line 700, in send
    raise ConnectionError(e, request=request)
requests.exceptions.ConnectionError: HTTPConnectionPool(host='127.0.0.1', port=5000): Max retries exceeded with url: /load_chat/ (Caused by NewConnectionError('<urllib3.connection.HTTPConnection object at 0x7248c1b52ff0>: Failed to establish a new connection: [Errno 111] Connection refused'))
2025-03-16 07:50:37.953 Uncaught app execution
Traceback (most recent call last):
  File "/home/azureuser/SDA/venv/lib/python3.12/site-packages/urllib3/connection.py", line 198, in _new_conn
    sock = connection.create_connection(
           ^^^^^^^^^^^^^^^^^^^^^^^^^^^^^
  File "/home/azureuser/SDA/venv/lib/python3.12/site-packages/urllib3/util/connection.py", line 85, in create_connection
    raise err
  File "/home/azureuser/SDA/venv/lib/python3.12/site-packages/urllib3/util/connection.py", line 73, in create_connection
    sock.connect(sa)
ConnectionRefusedError: [Errno 111] Connection refused

The above exception was the direct cause of the following exception:

Traceback (most recent call last):
  File "/home/azureuser/SDA/venv/lib/python3.12/site-packages/urllib3/connectionpool.py", line 787, in urlopen
    response = self._make_request(
               ^^^^^^^^^^^^^^^^^^^
  File "/home/azureuser/SDA/venv/lib/python3.12/site-packages/urllib3/connectionpool.py", line 493, in _make_request
    conn.request(
  File "/home/azureuser/SDA/venv/lib/python3.12/site-packages/urllib3/connection.py", line 445, in request
    self.endheaders()
  File "/usr/lib/python3.12/http/client.py", line 1331, in endheaders
    self._send_output(message_body, encode_chunked=encode_chunked)
  File "/usr/lib/python3.12/http/client.py", line 1091, in _send_output
    self.send(msg)
  File "/usr/lib/python3.12/http/client.py", line 1035, in send
    self.connect()
  File "/home/azureuser/SDA/venv/lib/python3.12/site-packages/urllib3/connection.py", line 276, in connect
    self.sock = self._new_conn()
                ^^^^^^^^^^^^^^^^
  File "/home/azureuser/SDA/venv/lib/python3.12/site-packages/urllib3/connection.py", line 213, in _new_conn
    raise NewConnectionError(
urllib3.exceptions.NewConnectionError: <urllib3.connection.HTTPConnection object at 0x737240110dd0>: Failed to establish a new connection: [Errno 111] Connection refused

The above exception was the direct cause of the following exception:

Traceback (most recent call last):
  File "/home/azureuser/SDA/venv/lib/python3.12/site-packages/requests/adapters.py", line 667, in send
    resp = conn.urlopen(
           ^^^^^^^^^^^^^
  File "/home/azureuser/SDA/venv/lib/python3.12/site-packages/urllib3/connectionpool.py", line 841, in urlopen
    retries = retries.increment(
              ^^^^^^^^^^^^^^^^^^
  File "/home/azureuser/SDA/venv/lib/python3.12/site-packages/urllib3/util/retry.py", line 519, in increment
    raise MaxRetryError(_pool, url, reason) from reason  # type: ignore[arg-type]
    ^^^^^^^^^^^^^^^^^^^^^^^^^^^^^^^^^^^^^^^^^^^^^^^^^^^
urllib3.exceptions.MaxRetryError: HTTPConnectionPool(host='127.0.0.1', port=5000): Max retries exceeded with url: /load_chat/ (Caused by NewConnectionError('<urllib3.connection.HTTPConnection object at 0x737240110dd0>: Failed to establish a new connection: [Errno 111] Connection refused'))

During handling of the above exception, another exception occurred:

Traceback (most recent call last):
  File "/home/azureuser/SDA/venv/lib/python3.12/site-packages/streamlit/runtime/scriptrunner/exec_code.py", line 88, in exec_func_with_error_handling
    result = func()
             ^^^^^^
  File "/home/azureuser/SDA/venv/lib/python3.12/site-packages/streamlit/runtime/scriptrunner/script_runner.py", line 579, in code_to_exec
    exec(code, module.__dict__)
  File "/home/azureuser/SDA/chatbot.py", line 112, in <module>
    load_chats_from_db()
  File "/home/azureuser/SDA/chatbot.py", line 23, in load_chats_from_db
    response = requests.get(LOAD_CHAT_URL)
               ^^^^^^^^^^^^^^^^^^^^^^^^^^^
  File "/home/azureuser/SDA/venv/lib/python3.12/site-packages/requests/api.py", line 73, in get
    return request("get", url, params=params, **kwargs)
           ^^^^^^^^^^^^^^^^^^^^^^^^^^^^^^^^^^^^^^^^^^^^
  File "/home/azureuser/SDA/venv/lib/python3.12/site-packages/requests/api.py", line 59, in request
    return session.request(method=method, url=url, **kwargs)
           ^^^^^^^^^^^^^^^^^^^^^^^^^^^^^^^^^^^^^^^^^^^^^^^^^
  File "/home/azureuser/SDA/venv/lib/python3.12/site-packages/requests/sessions.py", line 589, in request
    resp = self.send(prep, **send_kwargs)
           ^^^^^^^^^^^^^^^^^^^^^^^^^^^^^^
  File "/home/azureuser/SDA/venv/lib/python3.12/site-packages/requests/sessions.py", line 703, in send
    r = adapter.send(request, **kwargs)
        ^^^^^^^^^^^^^^^^^^^^^^^^^^^^^^^
  File "/home/azureuser/SDA/venv/lib/python3.12/site-packages/requests/adapters.py", line 700, in send
    raise ConnectionError(e, request=request)
requests.exceptions.ConnectionError: HTTPConnectionPool(host='127.0.0.1', port=5000): Max retries exceeded with url: /load_chat/ (Caused by NewConnectionError('<urllib3.connection.HTTPConnection object at 0x737240110dd0>: Failed to establish a new connection: [Errno 111] Connection refused'))
2025-03-16 07:53:29.101 Uncaught exception in write_error
Traceback (most recent call last):
  File "/home/azureuser/SDA/venv/lib/python3.12/site-packages/streamlit/web/server/routes.py", line 69, in validate_absolute_path
  File "/home/azureuser/SDA/venv/lib/python3.12/site-packages/tornado/web.py", line 2900, in validate_absolute_path
tornado.web.HTTPError: HTTP 404: Not Found

During handling of the above exception, another exception occurred:

Traceback (most recent call last):
  File "/home/azureuser/SDA/venv/lib/python3.12/site-packages/tornado/web.py", line 1790, in _execute
  File "/home/azureuser/SDA/venv/lib/python3.12/site-packages/tornado/web.py", line 2688, in get
  File "/home/azureuser/SDA/venv/lib/python3.12/site-packages/streamlit/web/server/routes.py", line 84, in validate_absolute_path
  File "/home/azureuser/SDA/venv/lib/python3.12/site-packages/tornado/web.py", line 2900, in validate_absolute_path
tornado.web.HTTPError: HTTP 404: Not Found

During handling of the above exception, another exception occurred:

Traceback (most recent call last):
  File "/home/azureuser/SDA/venv/lib/python3.12/site-packages/tornado/web.py", line 1298, in send_error
  File "/home/azureuser/SDA/venv/lib/python3.12/site-packages/streamlit/web/server/routes.py", line 91, in write_error
  File "/home/azureuser/SDA/venv/lib/python3.12/site-packages/tornado/web.py", line 944, in render
  File "/home/azureuser/SDA/venv/lib/python3.12/site-packages/tornado/web.py", line 1090, in render_string
  File "/home/azureuser/SDA/venv/lib/python3.12/site-packages/tornado/template.py", line 446, in load
  File "/home/azureuser/SDA/venv/lib/python3.12/site-packages/tornado/template.py", line 476, in _create_template
FileNotFoundError: [Errno 2] No such file or directory: '/home/azureuser/SDA/venv/lib/python3.12/site-packages/streamlit/static/index.html'
2025-03-16 07:53:32.200 Uncaught exception in write_error
Traceback (most recent call last):
  File "/home/azureuser/SDA/venv/lib/python3.12/site-packages/streamlit/web/server/routes.py", line 69, in validate_absolute_path
  File "/home/azureuser/SDA/venv/lib/python3.12/site-packages/tornado/web.py", line 2900, in validate_absolute_path
tornado.web.HTTPError: HTTP 404: Not Found

During handling of the above exception, another exception occurred:

Traceback (most recent call last):
  File "/home/azureuser/SDA/venv/lib/python3.12/site-packages/tornado/web.py", line 1790, in _execute
  File "/home/azureuser/SDA/venv/lib/python3.12/site-packages/tornado/web.py", line 2688, in get
  File "/home/azureuser/SDA/venv/lib/python3.12/site-packages/streamlit/web/server/routes.py", line 84, in validate_absolute_path
  File "/home/azureuser/SDA/venv/lib/python3.12/site-packages/tornado/web.py", line 2900, in validate_absolute_path
tornado.web.HTTPError: HTTP 404: Not Found

During handling of the above exception, another exception occurred:

Traceback (most recent call last):
  File "/home/azureuser/SDA/venv/lib/python3.12/site-packages/tornado/web.py", line 1298, in send_error
  File "/home/azureuser/SDA/venv/lib/python3.12/site-packages/streamlit/web/server/routes.py", line 91, in write_error
  File "/home/azureuser/SDA/venv/lib/python3.12/site-packages/tornado/web.py", line 944, in render
  File "/home/azureuser/SDA/venv/lib/python3.12/site-packages/tornado/web.py", line 1090, in render_string
  File "/home/azureuser/SDA/venv/lib/python3.12/site-packages/tornado/template.py", line 446, in load
  File "/home/azureuser/SDA/venv/lib/python3.12/site-packages/tornado/template.py", line 476, in _create_template
FileNotFoundError: [Errno 2] No such file or directory: '/home/azureuser/SDA/venv/lib/python3.12/site-packages/streamlit/static/index.html'
2025-03-16 07:53:34.970 Uncaught exception in write_error
Traceback (most recent call last):
  File "/home/azureuser/SDA/venv/lib/python3.12/site-packages/streamlit/web/server/routes.py", line 69, in validate_absolute_path
  File "/home/azureuser/SDA/venv/lib/python3.12/site-packages/tornado/web.py", line 2900, in validate_absolute_path
tornado.web.HTTPError: HTTP 404: Not Found

During handling of the above exception, another exception occurred:

Traceback (most recent call last):
  File "/home/azureuser/SDA/venv/lib/python3.12/site-packages/tornado/web.py", line 1790, in _execute
  File "/home/azureuser/SDA/venv/lib/python3.12/site-packages/tornado/web.py", line 2688, in get
  File "/home/azureuser/SDA/venv/lib/python3.12/site-packages/streamlit/web/server/routes.py", line 84, in validate_absolute_path
  File "/home/azureuser/SDA/venv/lib/python3.12/site-packages/tornado/web.py", line 2900, in validate_absolute_path
tornado.web.HTTPError: HTTP 404: Not Found

During handling of the above exception, another exception occurred:

Traceback (most recent call last):
  File "/home/azureuser/SDA/venv/lib/python3.12/site-packages/tornado/web.py", line 1298, in send_error
  File "/home/azureuser/SDA/venv/lib/python3.12/site-packages/streamlit/web/server/routes.py", line 91, in write_error
  File "/home/azureuser/SDA/venv/lib/python3.12/site-packages/tornado/web.py", line 944, in render
  File "/home/azureuser/SDA/venv/lib/python3.12/site-packages/tornado/web.py", line 1090, in render_string
  File "/home/azureuser/SDA/venv/lib/python3.12/site-packages/tornado/template.py", line 446, in load
  File "/home/azureuser/SDA/venv/lib/python3.12/site-packages/tornado/template.py", line 476, in _create_template
FileNotFoundError: [Errno 2] No such file or directory: '/home/azureuser/SDA/venv/lib/python3.12/site-packages/streamlit/static/index.html'
2025-03-16 07:58:32.445 Uncaught app execution
Traceback (most recent call last):
  File "/home/azureuser/SDA/venv/lib/python3.12/site-packages/urllib3/connection.py", line 198, in _new_conn
    sock = connection.create_connection(
           ^^^^^^^^^^^^^^^^^^^^^^^^^^^^^
  File "/home/azureuser/SDA/venv/lib/python3.12/site-packages/urllib3/util/connection.py", line 85, in create_connection
    raise err
  File "/home/azureuser/SDA/venv/lib/python3.12/site-packages/urllib3/util/connection.py", line 73, in create_connection
    sock.connect(sa)
ConnectionRefusedError: [Errno 111] Connection refused

The above exception was the direct cause of the following exception:

Traceback (most recent call last):
  File "/home/azureuser/SDA/venv/lib/python3.12/site-packages/urllib3/connectionpool.py", line 787, in urlopen
    response = self._make_request(
               ^^^^^^^^^^^^^^^^^^^
  File "/home/azureuser/SDA/venv/lib/python3.12/site-packages/urllib3/connectionpool.py", line 493, in _make_request
    conn.request(
  File "/home/azureuser/SDA/venv/lib/python3.12/site-packages/urllib3/connection.py", line 445, in request
    self.endheaders()
  File "/usr/lib/python3.12/http/client.py", line 1331, in endheaders
    self._send_output(message_body, encode_chunked=encode_chunked)
  File "/usr/lib/python3.12/http/client.py", line 1091, in _send_output
    self.send(msg)
  File "/usr/lib/python3.12/http/client.py", line 1035, in send
    self.connect()
  File "/home/azureuser/SDA/venv/lib/python3.12/site-packages/urllib3/connection.py", line 276, in connect
    self.sock = self._new_conn()
                ^^^^^^^^^^^^^^^^
  File "/home/azureuser/SDA/venv/lib/python3.12/site-packages/urllib3/connection.py", line 213, in _new_conn
    raise NewConnectionError(
urllib3.exceptions.NewConnectionError: <urllib3.connection.HTTPConnection object at 0x73cfb0f06150>: Failed to establish a new connection: [Errno 111] Connection refused

The above exception was the direct cause of the following exception:

Traceback (most recent call last):
  File "/home/azureuser/SDA/venv/lib/python3.12/site-packages/requests/adapters.py", line 667, in send
    resp = conn.urlopen(
           ^^^^^^^^^^^^^
  File "/home/azureuser/SDA/venv/lib/python3.12/site-packages/urllib3/connectionpool.py", line 841, in urlopen
    retries = retries.increment(
              ^^^^^^^^^^^^^^^^^^
  File "/home/azureuser/SDA/venv/lib/python3.12/site-packages/urllib3/util/retry.py", line 519, in increment
    raise MaxRetryError(_pool, url, reason) from reason  # type: ignore[arg-type]
    ^^^^^^^^^^^^^^^^^^^^^^^^^^^^^^^^^^^^^^^^^^^^^^^^^^^
urllib3.exceptions.MaxRetryError: HTTPConnectionPool(host='127.0.0.1', port=5000): Max retries exceeded with url: /load_chat/ (Caused by NewConnectionError('<urllib3.connection.HTTPConnection object at 0x73cfb0f06150>: Failed to establish a new connection: [Errno 111] Connection refused'))

During handling of the above exception, another exception occurred:

Traceback (most recent call last):
  File "/home/azureuser/SDA/venv/lib/python3.12/site-packages/streamlit/runtime/scriptrunner/exec_code.py", line 88, in exec_func_with_error_handling
    result = func()
             ^^^^^^
  File "/home/azureuser/SDA/venv/lib/python3.12/site-packages/streamlit/runtime/scriptrunner/script_runner.py", line 579, in code_to_exec
    exec(code, module.__dict__)
  File "/home/azureuser/SDA/chatbot.py", line 112, in <module>
    load_chats_from_db()
  File "/home/azureuser/SDA/chatbot.py", line 23, in load_chats_from_db
    response = requests.get(LOAD_CHAT_URL)
               ^^^^^^^^^^^^^^^^^^^^^^^^^^^
  File "/home/azureuser/SDA/venv/lib/python3.12/site-packages/requests/api.py", line 73, in get
    return request("get", url, params=params, **kwargs)
           ^^^^^^^^^^^^^^^^^^^^^^^^^^^^^^^^^^^^^^^^^^^^
  File "/home/azureuser/SDA/venv/lib/python3.12/site-packages/requests/api.py", line 59, in request
    return session.request(method=method, url=url, **kwargs)
           ^^^^^^^^^^^^^^^^^^^^^^^^^^^^^^^^^^^^^^^^^^^^^^^^^
  File "/home/azureuser/SDA/venv/lib/python3.12/site-packages/requests/sessions.py", line 589, in request
    resp = self.send(prep, **send_kwargs)
           ^^^^^^^^^^^^^^^^^^^^^^^^^^^^^^
  File "/home/azureuser/SDA/venv/lib/python3.12/site-packages/requests/sessions.py", line 703, in send
    r = adapter.send(request, **kwargs)
        ^^^^^^^^^^^^^^^^^^^^^^^^^^^^^^^
  File "/home/azureuser/SDA/venv/lib/python3.12/site-packages/requests/adapters.py", line 700, in send
    raise ConnectionError(e, request=request)
requests.exceptions.ConnectionError: HTTPConnectionPool(host='127.0.0.1', port=5000): Max retries exceeded with url: /load_chat/ (Caused by NewConnectionError('<urllib3.connection.HTTPConnection object at 0x73cfb0f06150>: Failed to establish a new connection: [Errno 111] Connection refused'))
2025-03-16 08:03:45.655 Uncaught app execution
Traceback (most recent call last):
  File "/home/azureuser/SDA/venv/lib/python3.12/site-packages/urllib3/connection.py", line 198, in _new_conn
    sock = connection.create_connection(
           ^^^^^^^^^^^^^^^^^^^^^^^^^^^^^
  File "/home/azureuser/SDA/venv/lib/python3.12/site-packages/urllib3/util/connection.py", line 85, in create_connection
    raise err
  File "/home/azureuser/SDA/venv/lib/python3.12/site-packages/urllib3/util/connection.py", line 73, in create_connection
    sock.connect(sa)
ConnectionRefusedError: [Errno 111] Connection refused

The above exception was the direct cause of the following exception:

Traceback (most recent call last):
  File "/home/azureuser/SDA/venv/lib/python3.12/site-packages/urllib3/connectionpool.py", line 787, in urlopen
    response = self._make_request(
               ^^^^^^^^^^^^^^^^^^^
  File "/home/azureuser/SDA/venv/lib/python3.12/site-packages/urllib3/connectionpool.py", line 493, in _make_request
    conn.request(
  File "/home/azureuser/SDA/venv/lib/python3.12/site-packages/urllib3/connection.py", line 445, in request
    self.endheaders()
  File "/usr/lib/python3.12/http/client.py", line 1331, in endheaders
    self._send_output(message_body, encode_chunked=encode_chunked)
  File "/usr/lib/python3.12/http/client.py", line 1091, in _send_output
    self.send(msg)
  File "/usr/lib/python3.12/http/client.py", line 1035, in send
    self.connect()
  File "/home/azureuser/SDA/venv/lib/python3.12/site-packages/urllib3/connection.py", line 276, in connect
    self.sock = self._new_conn()
                ^^^^^^^^^^^^^^^^
  File "/home/azureuser/SDA/venv/lib/python3.12/site-packages/urllib3/connection.py", line 213, in _new_conn
    raise NewConnectionError(
urllib3.exceptions.NewConnectionError: <urllib3.connection.HTTPConnection object at 0x7eda6f913410>: Failed to establish a new connection: [Errno 111] Connection refused

The above exception was the direct cause of the following exception:

Traceback (most recent call last):
  File "/home/azureuser/SDA/venv/lib/python3.12/site-packages/requests/adapters.py", line 667, in send
    resp = conn.urlopen(
           ^^^^^^^^^^^^^
  File "/home/azureuser/SDA/venv/lib/python3.12/site-packages/urllib3/connectionpool.py", line 841, in urlopen
    retries = retries.increment(
              ^^^^^^^^^^^^^^^^^^
  File "/home/azureuser/SDA/venv/lib/python3.12/site-packages/urllib3/util/retry.py", line 519, in increment
    raise MaxRetryError(_pool, url, reason) from reason  # type: ignore[arg-type]
    ^^^^^^^^^^^^^^^^^^^^^^^^^^^^^^^^^^^^^^^^^^^^^^^^^^^
urllib3.exceptions.MaxRetryError: HTTPConnectionPool(host='127.0.0.1', port=5000): Max retries exceeded with url: /load_chat/ (Caused by NewConnectionError('<urllib3.connection.HTTPConnection object at 0x7eda6f913410>: Failed to establish a new connection: [Errno 111] Connection refused'))

During handling of the above exception, another exception occurred:

Traceback (most recent call last):
  File "/home/azureuser/SDA/venv/lib/python3.12/site-packages/streamlit/runtime/scriptrunner/exec_code.py", line 88, in exec_func_with_error_handling
    result = func()
             ^^^^^^
  File "/home/azureuser/SDA/venv/lib/python3.12/site-packages/streamlit/runtime/scriptrunner/script_runner.py", line 579, in code_to_exec
    exec(code, module.__dict__)
  File "/home/azureuser/SDA/chatbot.py", line 112, in <module>
    load_chats_from_db()
  File "/home/azureuser/SDA/chatbot.py", line 23, in load_chats_from_db
    response = requests.get(LOAD_CHAT_URL)
               ^^^^^^^^^^^^^^^^^^^^^^^^^^^
  File "/home/azureuser/SDA/venv/lib/python3.12/site-packages/requests/api.py", line 73, in get
    return request("get", url, params=params, **kwargs)
           ^^^^^^^^^^^^^^^^^^^^^^^^^^^^^^^^^^^^^^^^^^^^
  File "/home/azureuser/SDA/venv/lib/python3.12/site-packages/requests/api.py", line 59, in request
    return session.request(method=method, url=url, **kwargs)
           ^^^^^^^^^^^^^^^^^^^^^^^^^^^^^^^^^^^^^^^^^^^^^^^^^
  File "/home/azureuser/SDA/venv/lib/python3.12/site-packages/requests/sessions.py", line 589, in request
    resp = self.send(prep, **send_kwargs)
           ^^^^^^^^^^^^^^^^^^^^^^^^^^^^^^
  File "/home/azureuser/SDA/venv/lib/python3.12/site-packages/requests/sessions.py", line 703, in send
    r = adapter.send(request, **kwargs)
        ^^^^^^^^^^^^^^^^^^^^^^^^^^^^^^^
  File "/home/azureuser/SDA/venv/lib/python3.12/site-packages/requests/adapters.py", line 700, in send
    raise ConnectionError(e, request=request)
requests.exceptions.ConnectionError: HTTPConnectionPool(host='127.0.0.1', port=5000): Max retries exceeded with url: /load_chat/ (Caused by NewConnectionError('<urllib3.connection.HTTPConnection object at 0x7eda6f913410>: Failed to establish a new connection: [Errno 111] Connection refused'))
